<mujoco>
  <option timestep="0.001" gravity="0 0 -9.81" impratio="0.00001" cone="elliptic"/>

  <asset>
    <!-- Materials and textures -->
    <texture name="ground_texture" type="2d" builtin="checker" width="512" height="512"
             rgb1="0.8 0.8 0.8" rgb2="0.2 0.3 0.3"/>
    <material name="ground_material" texture="ground_texture" texrepeat="20 20"
              reflectance="0.2"/>
    <material name="torso_material" rgba="0.6 0.3 0.3 1"/>
    <material name="leg_material" rgba="0.3 0.6 0.3 1"/>
    <material name="outer_leg_material" rgba="0.3 0.3 0.6 1"/>
    <material name="feet_material" rgba="0.8 0.4 0.2 1"/>
  </asset>

  <worldbody>
    <!-- Ground plane -->
    <geom name="ground" type="plane" size="20 20 0.1" material="ground_material" condim="3"/>

    <!-- Sloped plane -->
    <geom name="slope" type="plane" pos="0 0 0" euler="0 -2 0" size="15 15 10" material="ground_material"/> 

    <!-- Light source -->
    <light pos="10 0 30" dir="0 0 -1" diffuse="1 1 1" specular="0.5 0.5 0.5"/>

    <!-- Torso body -->
    <body name="torso" pos="10 0 1.4">

      <!-- Movement along y-axis -->
      <joint name="torso_slide_x" type="slide" axis="1 0 0"/> 
  
      <!-- Movement along z-axis -->
      <joint name="torso_slide_z" type="slide" axis="0 0 1"/> 
  
      <!-- Yaw around y-axis -->
      <joint name="torso_y_rot" type="hinge" axis="0 1 0"/> 

      <!-- Torso geometry -->
      <geom name="torso_geom" type="sphere" size="0.05" mass="10"
            material="torso_material"/>

      <!-- Left Leg -->
      <body name="left_leg" pos="0 -0.075 0" euler="0 0 0">
        <!-- Hip joint -->
        <joint name="left_hip" type="hinge" axis="0 -1 0" damping="0.0" frictionloss="0.0"/>  <!-- range="-45 45" -->
        <!-- Thigh geometry -->
        <geom name="left_thigh" type="capsule" fromto="0 0 0 0 0 -0.5" size="0.02"
              material="leg_material" mass="5"/>
        <!-- Knee joint -->
        <body name="left_shin" pos="0 0 -0.5">
          <joint name="left_knee" type="slide" axis="0 0 1" range="-0 0.25"/>
          <!-- Shin geometry -->
          <geom name="left_shin_geom" type="capsule" fromto="0 0 0 0 0 -0.5"
                size="0.015" material="leg_material" mass="0.0"/>
          <!-- Foot geometry -->
          <geom name="left_foot" type="ellipsoid" pos="0 0 -0.5" size="0.05 0.02 0.05"
                material="feet_material" mass="0.1  "/>
        </body>
      </body>

      <!-- Right Leg -->
      <body name="right_leg" pos="0 0.075 0" euler="0 15 0">
        <!-- Hip joint -->
        <joint name="right_hip" type="hinge" axis="0 -1 0" damping="0.0" frictionloss="0.0"/> <!-- range="-45 45" -->
        <!-- Thigh geometry -->
        <geom name="right_thigh" type="capsule" fromto="0 0 0 0 0 -0.5" size="0.02"
              material="leg_material"/>
        <!-- Knee joint -->
        <body name="right_shin" pos="0 0 -0.5">
          <joint name="right_knee" type="slide" axis="0 0 1" range="-0 0.25"/>
          <!-- Shin geometry -->
          <geom name="right_shin_geom" type="capsule" fromto="0 0 0 0 0 -0.5"
                size="0.015" material="leg_material" mass="0.0"/>
          <!-- Foot geometry -->
          <geom name="right_foot" type="ellipsoid" pos="0 0 -0.5" size="0.05 0.02 0.05"
                material="feet_material" mass="0.25"/>
        </body>
      </body>

    </body>
  </worldbody>

  <!--
  <actuator>
    <motor joint="left_hip" name="left_hip_motor"  ctrlrange="-1 1"/>
    <motor joint="right_hip" name="right_hip_motor" ctrlrange="-1 1"/>
    <motor joint="left_knee" name="left_knee_motor" ctrlrange="-0 0.25"/>
    <motor joint="right_knee" name="right_knee_motor" ctrlrange="-0 0.25"/>
  </actuator>
  -->

<actuator>
  
  <position joint="left_knee" name="left_knee_actuator" kp="500" kv="1" ctrlrange="-0.25 0.25"/>
  <position joint="right_knee" name="right_knee_actuator" kp="500" kv="1" ctrlrange="-0.25 0.25"/>

     <!--  
  <position joint="left_hip" name="left_hip_actuator" kp="200" kv="1" ctrlrange="-0.5 0.5"/>
  <position joint="right_hip" name="right_hip_actuator" kp="200" kv="1" ctrlrange="-0.5 0.5"/>
  -->
</actuator>


</mujoco>
